Workbook
Name AnticipoInicialProveedor: [1]DatosObra!$E$46
Name area: '[2]N_Campos Generales'!$C$21
Name Capacidad: '[3]N_Campos Especificos'!$D$85
Name CapacidadCarter: '[3]N_Campos Especificos'!$D$27
Name CapacidadContratacion: '[4]Cargos Adicionales'!#REF!
Name CapacidadContratacion: '[4]Cargos Adicionales'!#REF!
Name CapacidadContratacion: '[4]Cargos Adicionales'!#REF!
Name CapacidadContratacion: '[4]Cargos Adicionales'!#REF!
Name CapacidadContratacion: '[4]Cargos Adicionales'!#REF!
Name CapacidadContratacion: '[4]Cargos Adicionales'!#REF!
Name CapacidadContratacion: '[4]Cargos Adicionales'!#REF!
Name CapacidadContratacion: '[4]Cargos Adicionales'!#REF!
Name CapacidadContratacion: '[4]Cargos Adicionales'!#REF!
Name CapacidadContratacion: '[4]Cargos Adicionales'!#REF!
Name CapacidadContratacion: '[4]Cargos Adicionales'!#REF!
Name cargo: '[2]N_Campos Generales'!$C$18
Name CargoAdicional: [5]Datos!$C$7
Name CI: '[4]Cargos Adicionales'!#REF!
Name CI: '[4]Cargos Adicionales'!#REF!
Name CI: '[4]Cargos Adicionales'!#REF!
Name CI: '[4]Cargos Adicionales'!#REF!
Name CI: '[4]Cargos Adicionales'!#REF!
Name CI: '[4]Cargos Adicionales'!#REF!
Name CI: '[4]Cargos Adicionales'!#REF!
Name CI: '[4]Cargos Adicionales'!#REF!
Name CI: '[4]Cargos Adicionales'!#REF!
Name CI: '[4]Cargos Adicionales'!#REF!
Name CI: '[4]Cargos Adicionales'!#REF!
Name CodigoEquipo: '[3]N_Campos Especificos'!$D$81
Name Combustible: '[3]N_Campos Especificos'!$D$20
Name Combustible_Formula: '[3]N_Campos Especificos'!$L$8
Name CombustibleA_Monto: '[3]N_Campos Especificos'!$O$8
Name CombustibleE_Monto: '[3]N_Campos Especificos'!$P$8
Name CombustibleE_Porcentaje: '[3]N_Campos Especificos'!$I$8
Name CombustibleR_Monto: '[3]N_Campos Especificos'!$Q$8
Name CombustibleR_Porcentaje: '[3]N_Campos Especificos'!$J$8
Name CombustibleSustitucion: '[3]N_Campos Especificos'!$N$8
Name ConsumoGa: '[3]N_Campos Especificos'!$E$29
Name Costo_directo: [2]DatosObra!$E$3
Name CostoActivo: '[3]N_Campos Especificos'!$E$57
Name CostoCargoFijoA: '[3]N_Campos Especificos'!$E$54
Name CostoCargoFijoE: '[3]N_Campos Especificos'!$E$55
Name CostoCargoFijoR: '[3]N_Campos Especificos'!$E$56
Name CostoCombustible: '[3]N_Campos Especificos'!$D$21
Name CostoConsumoA: '[3]N_Campos Especificos'!$O$15
Name CostoDirecto: [5]Datos!$C$14
Name CostoDirectoMasIndirecto: [1]DatosObra!$D$90
Name CostoEspera: '[3]N_Campos Especificos'!$E$58
Name CostoLubricante: '[3]N_Campos Especificos'!$D$23
Name CostoOperacionA: '[3]N_Campos Especificos'!$O$17
Name CostoOperacionE: '[3]N_Campos Especificos'!$P$17
Name CostoOperacionR: '[3]N_Campos Especificos'!$Q$17
Name CostoPzsEsp: '[3]N_Campos Especificos'!$D$8
Name CostoReserva: '[3]N_Campos Especificos'!$E$59
Name DecimalesRedondeo: [5]Datos!$C$15
Name departamento: '[2]N_Campos Generales'!$C$22
Name Depreciacion_Formula: '[3]N_Campos Especificos'!$L$4
Name Depreciacion_Sustitucion: '[3]N_Campos Especificos'!$N$4
Name DepreciacionA_Monto: '[3]N_Campos Especificos'!$O$4
Name DepreciacionE_Monto: '[3]N_Campos Especificos'!$P$4

Sheet 1) FSBC
A1: DICAL | B1: DÍAS CALENDARIO | H1: 365
A2: DIAGI | B2: DÍAS DE AGUINALDO | H2: 45
A3: PIVAC | B3: DÍAS POR PRIMA VACACIONAL | H3: 4
B4: Prima dominical | H4: 0
A5: Tp | B5: TOTAL DE DÍAS REALMENTE PAGADOS AL AÑO | G5: SUMA: | H5: =SUM(H1:H4) -> 414
A6: DIDOM | B6: DÍAS DOMINGO EN EL AÑO | H6: 52
A7: DIVAC | B7: DÍAS DE VACACIONES POR AÑO | H7: 15
A8: DIFEO | B8: DÍAS FESTIVOS OFICIALES POR AÑO | H8: 7
A9: DISIN | B9: DÍAS POR CONDICIONES SINDICALES ANUALES | H9: 7
A10: DICAU | B10: DÍAS PERDIDOS POR OTRAS CAUSAS | H10: 2
A11: DINLA | B11: DÍAS NO LABORADOS AL AÑO | G11: SUMA: | H11: =SUM(H6:H10) -> 83
A13: Tl | B13: TOTAL DE DÍAS REALMENTE LABORADOS AL AÑO (DICAL)-(DINLA) | H13: =H1-H11 -> 282
A15: Tp / Tl | B15: DÍAS PAGADOS / DÍAS LABORADOS | H15: =H5/H13 -> 1.4680851
A16: FSBC | B16: FACTOR DE SALARIO BASE DE COTIZACIÓN ( Tp-Te) / DICAL para cálculo de IMSS | H16: =H5/H1 -> 1.1342466

Sheet 2) FST
A1: Año | D1: 2026 | F1: se ocupa el año en el cual se esta ejecutando
A2: Salario mínimo: | D2: 315.04
A3: Salario mínimo frontera norte: | D3: 440.87 | O3: tabla de la hora 39 del manual, todo factor arriba de 1.95 o por debajo de 1.75. hay que checarlo
A4: UMA: | D4: 117.31 | G4: grupos salariales del contrato colectivo suterm
A5: UMAx3: | D5: =D4*3 -> 351.93
F6: Grupo 1 | G6: Grupo 2 | H6: Grupo 3 | I6: Grupo 4 | J6: Grupo 5 | K6: Grupo 6 | L6: Grupo 7 | M6: Grupo 8
A7: Salario del trabajador del SUTERM | F7: 278.8 | G7: 283.62 | H7: 315.64 | I7: 351.89 | J7: 543.83 | K7: 690.97 | L7: 767.86 | M7: 864.98
A9: Salario de mercado en la zona | F9: 315.04 | G9: 315.04 | H9: =H7 -> 315.64 | I9: =I7 -> 351.89 | J9: =J7 -> 543.83 | K9: =K7 -> 690.97 | L9: =L7 -> 767.86 | M9: =M7 -> 864.98
A10: Salario mínimo aplicable | F10: 315.04 | G10: 315.04 | H10: 315.04 | I10: 315.04 | J10: 315.04 | K10: 315.04 | L10: 315.04 | M10: 315.04 | O10: si el salario minimo es mayor que el salario del suterm se utiliza el salario minimo
A11: Salario mínimo en UMAS | F11: =F10/$D$4 -> 2.6855341 | G11: =G10/$D$4 -> 2.6855341 | H11: =H10/$D$4 -> 2.6855341 | I11: =I10/$D$4 -> 2.6855341 | J11: =J10/$D$4 -> 2.6855341 | K11: =K10/$D$4 -> 2.6855341 | L11: =L10/$D$4 -> 2.6855341 | M11: =M10/$D$4 -> 2.6855341
A12: Factor de mercado en la Zona | F12: =F9/F7 -> 1.1299857 | G12: =G9/G7 -> 1.110782 | H12: =H9/H7 -> 1 | I12: =I9/I7 -> 1 | J12: =J9/J7 -> 1 | K12: =K9/K7 -> 1 | L12: =L9/L7 -> 1 | M12: =M9/M7 -> 1
A14: Salario en UMA's | F14: =F9/$D$4 -> 2.6855341 | G14: =G9/$D$4 -> 2.6855341 | H14: =H9/$D$4 -> 2.6906487 | I14: =I9/$D$4 -> 2.999659 | J14: =J9/$D$4 -> 4.6358367 | K14: =K9/$D$4 -> 5.8901202 | L14: =L9/$D$4 -> 6.545563 | M14: =M9/$D$4 -> 7.3734549
A15: Factor de salario base de cotización | F15: ='[4]1) FSBC'!$H$16 -> 1.1315068 | G15: ='[4]1) FSBC'!$H$16 -> 1.1315068 | H15: ='[4]1) FSBC'!$H$16 -> 1.1315068 | I15: ='[4]1) FSBC'!$H$16 -> 1.1315068 | J15: ='[4]1) FSBC'!$H$16 -> 1.1315068 | K15: ='[4]1) FSBC'!$H$16 -> 1.1315068 | L15: ='[4]1) FSBC'!$H$16 -> 1.1315068 | M15: ='[4]1) FSBC'!$H$16 -> 1.1315068
A16: Salario base de cotización (IMSS) en UMAS | F16: =F15*F14 -> 3.0387002 | G16: =G15*G14 -> 3.0387002 | H16: =H15*H14 -> 3.0444874 | I16: =I15*I14 -> 3.3941347 | J16: =J15*J14 -> 5.2454809 | K16: =K15*K14 -> 6.6647113 | L16: =L15*L14 -> 7.4063494 | M16: =M15*M14 -> 8.3431148
A17: Salario base de cotización (IMSS) | F17: =F15*F9 -> 356.46992 | G17: =G15*G9 -> 356.46992 | H17: =H15*H9 -> 357.14882 | I17: =I15*I9 -> 398.16595 | J17: =J15*J9 -> 615.34737 | K17: =K15*K9 -> 781.83729 | L17: =L15*L9 -> 868.83885 | M17: =M15*M9 -> 978.73079
A18: Diferencia 3 UMAS | F18: =IF((F16-3)>0,(F16-3),0) -> 0.038700177 | G18: =IF((G16-3)>0,(G16-3),0) -> 0.038700177 | H18: =IF((H16-3)>0,(H16-3),0) -> 0.044487443 | I18: =IF((I16-3)>0,(I16-3),0) -> 0.39413473 | J18: =IF((J16-3)>0,(J16-3),0) -> 2.2454809 | K18: =IF((K16-3)>0,(K16-3),0) -> 3.6647113 | L18: =IF((L16-3)>0,(L16-3),0) -> 4.4063494 | M18: =IF((M16-3)>0,(M16-3),0) -> 5.3431148 | O18: este valor es la resta por 3 VECES UMA MENOS SALARIO BASE EN UMAS
C20: Patrón | D20: Trabajador | E20: Total
A21: Riesgo de trabajo | C21: 0.0758875 | E21: =SUM(C21:D21) -> 0.0758875 | F21: =$E21*F$16 -> 0.23059936 | G21: =$E21*G$16 -> 0.23059936 | H21: =$E21*H$16 -> 0.23103854 | I21: =$E21*I$16 -> 0.2575724 | J21: =$E21*J$16 -> 0.39806644 | K21: =$E21*K$16 -> 0.50576828 | L21: =$E21*L$16 -> 0.56204934 | M21: =$E21*M$16 -> 0.63313812
A23: Seguro de enfermedad y maternidad | B23: Cuota fija | C23: 0.204 | E23: =SUM(C23:D23) -> 0.204 | F23: =$E23*1 -> 0.204 | G23: =$E23*1 -> 0.204 | H23: =$E23*1 -> 0.204 | I23: =$E23*1 -> 0.204 | J23: =$E23*1 -> 0.204 | K23: =$E23*1 -> 0.204 | L23: =$E23*1 -> 0.204 | M23: =$E23*1 -> 0.204
B24: Cuota adicional | C24: 0.011 | D24: 0.004 | E24: =SUM(C24:D24) -> 0.015 | F24: =$E24*F$18 -> 0.00058050266 | G24: =$E24*G$18 -> 0.00058050266 | H24: =$E24*H$18 -> 0.00066731164 | I24: =$E24*I$18 -> 0.005912021 | J24: =$E24*J$18 -> 0.033682214 | K24: =$E24*K$18 -> 0.05497067 | L24: =$E24*L$18 -> 0.066095241 | M24: =$E24*M$18 -> 0.080146722
B25: Gastos medicos | C25: 0.0105 | D25: 0.00375 | E25: =SUM(C25:D25) -> 0.01425 | F25: =$E25*F$16 -> 0.043301478 | G25: =$E25*G$16 -> 0.043301478 | H25: =$E25*H$16 -> 0.043383946 | I25: =$E25*I$16 -> 0.04836642 | J25: =$E25*J$16 -> 0.074748103 | K25: =$E25*K$16 -> 0.094972137 | L25: =$E25*L$16 -> 0.10554048 | M25: =$E25*M$16 -> 0.11888939
B26: En dinero | C26: 0.007 | D26: 0.0025 | E26: =SUM(C26:D26) -> 0.0095 | F26: =$E26*F$16 -> 0.028867652 | G26: =$E26*G$16 -> 0.028867652 | H26: =$E26*H$16 -> 0.028922631 | I26: =$E26*I$16 -> 0.03224428 | J26: =$E26*J$16 -> 0.049832069 | K26: =$E26*K$16 -> 0.063314758 | L26: =$E26*L$16 -> 0.070360319 | M26: =$E26*M$16 -> 0.07925959
A28: Invalidez y vida | B28: En especie y dinero | C28: 0.0175 | D28: 0.00625 | E28: =SUM(C28:D28) -> 0.02375 | F28: =$E28*F$16 -> 0.072169129 | G28: =$E28*G$16 -> 0.072169129 | H28: =$E28*H$16 -> 0.072306577 | I28: =$E28*I$16 -> 0.0806107 | J28: =$E28*J$16 -> 0.12458017 | K28: =$E28*K$16 -> 0.15828689 | L28: =$E28*L$16 -> 0.1759008 | M28: =$E28*M$16 -> 0.19814898
A30: Invalidez y vida | B30: retiro | C30: 0.02 | E30: =SUM(C30:D30) -> 0.02 | F30: =$E30*F$16 -> 0.060774004 | G30: =$E30*G$16 -> 0.060774004 | H30: =$E30*H$16 -> 0.060889749 | I30: =$E30*I$16 -> 0.067882695 | J30: =$E30*J$16 -> 0.10490962 | K30: =$E30*K$16 -> 0.13329423 | L30: =$E30*L$16 -> 0.14812699 | M30: =$E30*M$16 -> 0.1668623
B31: Cesantia en edad avanzada y vejez | C31: Rango | F31: =IF(F16=1,1,IF(AND(F9>1,F16<=1.5),2,IF(AND(F16>1.5,F16<=2),3,IF(AND(F16>2,F16<=2.5),4,IF(AND(F16>2.5,F16<=3),5,IF(AND(F16>3,F16<=3.5),6,IF(AND(F16>3.5,F16<=4),7,IF(F16>4,8)))))))) -> 6 | G31: =IF(G16=1,1,IF(AND(G9>1,G16<=1.5),2,IF(AND(G16>1.5,G16<=2),3,IF(AND(G16>2,G16<=2.5),4,IF(AND(G16>2.5,G16<=3),5,IF(AND(G16>3,G16<=3.5),6,IF(AND(G16>3.5,G16<=4),7,IF(G16>4,8)))))))) -> 6 | H31: =IF(H16=1,1,IF(AND(H9>1,H16<=1.5),2,IF(AND(H16>1.5,H16<=2),3,IF(AND(H16>2,H16<=2.5),4,IF(AND(H16>2.5,H16<=3),5,IF(AND(H16>3,H16<=3.5),6,IF(AND(H16>3.5,H16<=4),7,IF(H16>4,8)))))))) -> 6 | I31: =IF(I16=1,1,IF(AND(I9>1,I16<=1.5),2,IF(AND(I16>1.5,I16<=2),3,IF(AND(I16>2,I16<=2.5),4,IF(AND(I16>2.5,I16<=3),5,IF(AND(I16>3,I16<=3.5),6,IF(AND(I16>3.5,I16<=4),7,IF(I16>4,8)))))))) -> 6 | J31: =IF(J16=1,1,IF(AND(J9>1,J16<=1.5),2,IF(AND(J16>1.5,J16<=2),3,IF(AND(J16>2,J16<=2.5),4,IF(AND(J16>2.5,J16<=3),5,IF(AND(J16>3,J16<=3.5),6,IF(AND(J16>3.5,J16<=4),7,IF(J16>4,8)))))))) -> 8 | K31: =IF(K16=1,1,IF(AND(K9>1,K16<=1.5),2,IF(AND(K16>1.5,K16<=2),3,IF(AND(K16>2,K16<=2.5),4,IF(AND(K16>2.5,K16<=3),5,IF(AND(K16>3,K16<=3.5),6,IF(AND(K16>3.5,K16<=4),7,IF(K16>4,8)))))))) -> 8 | L31: =IF(L16=1,1,IF(AND(L9>1,L16<=1.5),2,IF(AND(L16>1.5,L16<=2),3,IF(AND(L16>2,L16<=2.5),4,IF(AND(L16>2.5,L16<=3),5,IF(AND(L16>3,L16<=3.5),6,IF(AND(L16>3.5,L16<=4),7,IF(L16>4,8)))))))) -> 8 | M31: =IF(M16=1,1,IF(AND(M9>1,M16<=1.5),2,IF(AND(M16>1.5,M16<=2),3,IF(AND(M16>2,M16<=2.5),4,IF(AND(M16>2.5,M16<=3),5,IF(AND(M16>3,M16<=3.5),6,IF(AND(M16>3.5,M16<=4),7,IF(M16>4,8)))))))) -> 8
C32: % por rango | F32: =VLOOKUP(F31,'[4]Invalidez y vida NR'!$A$3:$J$10,HLOOKUP($D$1,'[4]Invalidez y vida NR'!$C$1:$J$2,2,FALSE),FALSE) -> 0.06361 | G32: =VLOOKUP(G31,'[4]Invalidez y vida NR'!$A$3:$J$10,HLOOKUP($D$1,'[4]Invalidez y vida NR'!$C$1:$J$2,2,FALSE),FALSE) -> 0.06361 | H32: =VLOOKUP(H31,'[4]Invalidez y vida NR'!$A$3:$J$10,HLOOKUP($D$1,'[4]Invalidez y vida NR'!$C$1:$J$2,2,FALSE),FALSE) -> 0.06361 | I32: =VLOOKUP(I31,'[4]Invalidez y vida NR'!$A$3:$J$10,HLOOKUP($D$1,'[4]Invalidez y vida NR'!$C$1:$J$2,2,FALSE),FALSE) -> 0.06361 | J32: =VLOOKUP(J31,'[4]Invalidez y vida NR'!$A$3:$J$10,HLOOKUP($D$1,'[4]Invalidez y vida NR'!$C$1:$J$2,2,FALSE),FALSE) -> 0.07513 | K32: =VLOOKUP(K31,'[4]Invalidez y vida NR'!$A$3:$J$10,HLOOKUP($D$1,'[4]Invalidez y vida NR'!$C$1:$J$2,2,FALSE),FALSE) -> 0.07513 | L32: =VLOOKUP(L31,'[4]Invalidez y vida NR'!$A$3:$J$10,HLOOKUP($D$1,'[4]Invalidez y vida NR'!$C$1:$J$2,2,FALSE),FALSE) -> 0.07513 | M32: =VLOOKUP(M31,'[4]Invalidez y vida NR'!$A$3:$J$10,HLOOKUP($D$1,'[4]Invalidez y vida NR'!$C$1:$J$2,2,FALSE),FALSE) -> 0.07513
C33: Variable | D33: 0.01125 | E33: =SUM(C33:D33) -> 0.01125 | F33: =(IF(F9=F11,0,$E33)+F32)*F$16 -> 0.2274771 | G33: =(IF(G9=G11,0,$E33)+G32)*G$16 -> 0.2274771 | H33: =(IF(H9=H11,0,$E33)+H32)*H$16 -> 0.22791033 | I33: =(IF(I9=I11,0,$E33)+I32)*I$16 -> 0.25408493 | J33: =(IF(J9=J11,0,$E33)+J32)*J$16 -> 0.45310464 | K33: =(IF(K9=K11,0,$E33)+K32)*K$16 -> 0.57569777 | L33: =(IF(L9=L11,0,$E33)+L32)*L$16 -> 0.63976046 | M33: =(IF(M9=M11,0,$E33)+M32)*M$16 -> 0.72067825
A35: Guarderia y prestaciones | D35: 0.01 | E35: =SUM(C35:D35) -> 0.01 | F35: =$E35*F$16 -> 0.030387002 | G35: =$E35*G$16 -> 0.030387002 | H35: =$E35*H$16 -> 0.030444874 | I35: =$E35*I$16 -> 0.033941347 | J35: =$E35*J$16 -> 0.052454809 | K35: =$E35*K$16 -> 0.066647113 | L35: =$E35*L$16 -> 0.074063494 | M35: =$E35*M$16 -> 0.083431148
A37: Prestaciones IMSS | F37: =F35+F33+F30+F28+F26+F25+F24+F23+F21 -> 0.89815622 | G37: =G35+G33+G30+G28+G26+G25+G24+G23+G21 -> 0.89815622 | H37: =H35+H33+H30+H28+H26+H25+H24+H23+H21 -> 0.89956396 | I37: =I35+I33+I30+I28+I26+I25+I24+I23+I21 -> 0.98461479 | J37: =J35+J33+J30+J28+J26+J25+J24+J23+J21 -> 1.4953781 | K37: =K35+K33+K30+K28+K26+K25+K24+K23+K21 -> 1.8569518 | L37: =L35+L33+L30+L28+L26+L25+L24+L23+L21 -> 2.0458971 | M37: =M35+M33+M30+M28+M26+M25+M24+M23+M21 -> 2.2845545
A39: Prestaciones Infonavit | C39: 0.05 | E39: =SUM(C39:C39) -> 0.05 | F39: =$E39*F$16 -> 0.15193501 | G39: =$E39*G$16 -> 0.15193501 | H39: =$E39*H$16 -> 0.15222437 | I39: =$E39*I$16 -> 0.16970674 | J39: =$E39*J$16 -> 0.26227405 | K39: =$E39*K$16 -> 0.33323557 | L39: =$E39*L$16 -> 0.37031747 | M39: =$E39*M$16 -> 0.41715574
A41: Suma de prestaciones | F41: =F39+F37 -> 1.0500912 | G41: =G39+G37 -> 1.0500912 | H41: =H39+H37 -> 1.0517883 | I41: =I39+I37 -> 1.1543215 | J41: =J39+J37 -> 1.7576521 | K41: =K39+K37 -> 2.1901874 | L41: =L39+L37 -> 2.4162146 | M41: =M39+M37 -> 2.7017102
A42: Obligación Obrero-Patronal (PS) (prestaciones/salario base UMAS) | F42: =F41/F16 -> 0.3455725 | G42: =G41/G16 -> 0.3455725 | H42: =H41/H16 -> 0.34547304 | I42: =I41/I16 -> 0.34009302 | J42: =J41/J16 -> 0.33507931 | K42: =K41/K16 -> 0.3286245 | L42: =L41/L16 -> 0.32623557 | M42: =M41/M16 -> 0.32382513
A43: Tp / Tl | F43: ='[4]1) FSBC'!$H$15 -> 1.464539 | G43: ='[4]1) FSBC'!$H$15 -> 1.464539 | H43: ='[4]1) FSBC'!$H$15 -> 1.464539 | I43: ='[4]1) FSBC'!$H$15 -> 1.464539 | J43: ='[4]1) FSBC'!$H$15 -> 1.464539 | K43: ='[4]1) FSBC'!$H$15 -> 1.464539 | L43: ='[4]1) FSBC'!$H$15 -> 1.464539 | M43: ='[4]1) FSBC'!$H$15 -> 1.464539
A44: Ps x (Tp/Tl) | F44: =F42*F43 -> 0.50610441 | G44: =G42*G43 -> 0.50610441 | H44: =H42*H43 -> 0.50595874 | I44: =I42*I43 -> 0.49807949 | J44: =J42*J43 -> 0.49073671 | K44: =K42*K43 -> 0.48128339 | L44: =L42*L43 -> 0.47778471 | M44: =M42*M43 -> 0.47425454
A45: Fsr= Ps (Tp / Tl ) + (Tp/Tl) | F45: =SUM(F43:F44) -> 1.9706434 | G45: =SUM(G43:G44) -> 1.9706434 | H45: =SUM(H43:H44) -> 1.9704977 | I45: =SUM(I43:I44) -> 1.9626185 | J45: =SUM(J43:J44) -> 1.9552757 | K45: =SUM(K43:K44) -> 1.9458224 | L45: =SUM(L43:L44) -> 1.9423237 | M45: =SUM(M43:M44) -> 1.9387935
A46: Salario Real (SR) | F46: =F45*F9 -> 620.8315 | G46: =G45*G9 -> 620.8315 | H46: =H45*H9 -> 621.96791 | I46: =I45*I9 -> 690.62582 | J46: =J45*J9 -> 1063.3376 | K46: =K45*K9 -> 1344.5049 | L46: =L45*L9 -> 1491.4327 | M46: =M45*M9 -> 1677.0176

Sheet Salarios
C3: MANO DE OBRA
C4: Descripción | D4: Salario Tabulado SUTERM | E4: F.S.R. | F4: Total, del Salario Real
C6: AYUDANTE OFICIAL | D6: ='2) FST'!H9 -> 315.64 | E6: ='2) FST'!H45 -> 1.9704977 | F6: =D6*E6 -> 621.96791
C7: OFICIAL PINTOR | D7: ='2) FST'!I9 -> 351.89 | E7: ='2) FST'!I$45 -> 1.9626185 | F7: =D7*E7 -> 690.62582
C8: OFICIAL LAMINERO | D8: ='2) FST'!I9 -> 351.89 | E8: ='2) FST'!I$45 -> 1.9626185 | F8: =D8*E8 -> 690.62582
C9: OFICIAL AISLADOR | D9: ='2) FST'!I9 -> 351.89 | E9: ='2) FST'!I$45 -> 1.9626185 | F9: =D9*E9 -> 690.62582
C10: OFICIAL ALBAÑIL | D10: ='2) FST'!I9 -> 351.89 | E10: ='2) FST'!I$45 -> 1.9626185 | F10: =D10*E10 -> 690.62582
C11: CABO DE OFICIO | D11: ='2) FST'!J9 -> 543.83 | E11: ='2) FST'!J45 -> 1.9552757 | F11: =D11*E11 -> 1063.3376
C12: CHOFER | D12: ='2) FST'!G9 -> 315.04 | E12: ='2) FST'!G45 -> 1.9706434 | F12: =D12*E12 -> 620.8315 | G12: SE TOMA EL SALARIO MINIMO YA QUE ES MAYOR QUE EL DEL SUTERM
C13: AYUDANTE GENERAL | D13: ='2) FST'!G9 -> 315.04 | E13: =E12 -> 1.9706434 | F13: =D13*E13 -> 620.8315 | G13: SE TOMA EL SALARIO MINIMO YA QUE ES MAYOR QUE EL DEL SUTERM

Sheet CUADR 1
C2: LICITACIÓN | H2: ANEXO
C4: PARA: | D4: =Catalogo!E3 -> OBRA, MANTENIMIENTO A UNIDADES 1, 2 Y 4 DE LA C.T. EMILIO PORTES GIL INSTALACIÓN DE AISLAMIENTOS TÉRMICOS PARA EL PARO PROGRAMADO DEL AÑO 2026 | H4: 11
A6: NOMBRE O RAZÓN SOCIAL DEL LICITANTE: | D6: FIRMA DEL LICITANTE: | G6: SUBDIRECCIÓN DE:
A10: ANÁLISIS DE LOS PRECIOS UNITARIOS DE LOS CONCEPTOS DE TRABAJO DEL CATÁLOGO | H10: HOJA: 1
H11: DE 4
A13: =Catalogo!A12 -> 1 | B13: CONCEPTO: | C13: CUADRILLA no.1 PINTURA (0.2 DE CABO DE OF. + 1 OF. PINTORES + 1 AYUD. OFICIAL ) | G13: UNIDAD | H13: JORNAL
G14: CANTIDAD | H14: 1
A15: MATERIALES
A16: DESCRIPCIÓN | E16: UNIDAD | F16: Pm | G16: Cm | H16: M=Pm x Cm
F28: SUMA 1 | H28: =SUM(H17:H27) -> 0
A29: MANO DE OBRA
A30: CATEGORÍA | C30: UNIDAD | D30: SALARIO (a) | E30: CANT (b) | F30: Sr=(a) x (b) | G30: R | H30: Mo = Sr / R
A31: =Salarios!C11 -> CABO DE OFICIO | C31: jor | D31: =Salarios!F11 -> 1063.3376 | E31: =2/10 -> 0.2 | F31: =+D31*E31 -> 212.66752 | G31: 1 | H31: =F31/G31 -> 212.66752
A32: =Salarios!C7 -> OFICIAL PINTOR | C32: jor | D32: =Salarios!F7 -> 690.62582 | E32: 1 | F32: =+D32*E32 -> 690.62582 | G32: 1 | H32: =F32/G32 -> 690.62582
A33: =Salarios!C6 -> AYUDANTE OFICIAL | C33: jor | D33: =Salarios!F6 -> 621.96791 | E33: 1 | F33: =+D33*E33 -> 621.96791 | G33: 1 | H33: =F33/G33 -> 621.96791
F34: SUMA 2 | H34: =SUM(H31:H33) -> 1525.2613
A35: MAQUINARIA Y EQUIPO DE CONSTRUCCIÓN
A36: DESCRIPCIÓN | E36: UNIDAD | F36: Phm | G36: Rhm | H36: ME = Phm / Rhm
F41: SUMA 3 | H41: =SUM(H37:H40) -> 0
A42: HERRAMIENTA Y EQUIPO DE SEGURIDAD
A43: Herramienta de mano | F43: Kh | G43: Mo | H43: Hm = Kh X Mo
H44: =+F44*G44 -> 0
A45: Equipo de seguridad | F45: Ks | G45: Mo | H45: Es = Ks X Mo
H46: =+F46*G46 -> 0
F47: SUMA 4 | H47: =+H44+H46 -> 0
A48: (CD) COSTO DIRECTO (Suma 1 + 2 + 3 + 4) | H48: =+H28+H34+H41+H47 -> 1525.2613
J52: FORMULACIÓN DE CUADRILLAS
J53: NUMERO | K53: DESCRIPCIÓN | P53: SALARIO
J54: CUAD 1 | K54: =C13 -> CUADRILLA no.1 PINTURA (0.2 DE CABO DE OF. + 1 OF. PINTORES + 1 AYUD. OFICIAL ) | P54: =H48 -> 1525.2613
J55: CUAD 2 | K55: ='CUADR 2'!C13 -> CUADRILLA no.2 ALBAÑILERIA (0.2 DE CABO DE OF. + 1 OF. ALBAÑIL + 1 AY. OFICIALES) | P55: ='CUADR 2'!H48 -> 1525.2613
J56: CUAD 3 | K56: ='CUADR 3'!C13 -> CUADRILLA no.3 AISLAMIENTOS (0.3 DE CABO DE OF 1 OF. AISLADOR + 2 AYUD OFICIAL.) | P56: ='CUADR 3'!H48 -> 2253.5629
J57: CUAD 4 | K57: ='CUADR 4'!C13 -> CUADRILLA no.4 LAMINEROS (0.6 DE CABO DE OF 2 OF. LAMINEROS + 2 AYUD OFICIAL+ 2 AYUDANTES GENERALES.) | P57: ='CUADR 4'!H49 -> 4504.853

Sheet CUADR 2
C2: LICITACIÓN | H2: ANEXO
C4: PARA: | D4: =Catalogo!E3 -> OBRA, MANTENIMIENTO A UNIDADES 1, 2 Y 4 DE LA C.T. EMILIO PORTES GIL INSTALACIÓN DE AISLAMIENTOS TÉRMICOS PARA EL PARO PROGRAMADO DEL AÑO 2026 | H4: 11
A6: NOMBRE O RAZÓN SOCIAL DEL LICITANTE: | D6: FIRMA DEL LICITANTE: | G6: SUBDIRECCIÓN DE:
A10: ANÁLISIS DE LOS PRECIOS UNITARIOS DE LOS CONCEPTOS DE TRABAJO DEL CATÁLOGO | H10: HOJA: 2
H11: DE 4
A13: =Catalogo!A12 -> 1 | B13: CONCEPTO: | C13: CUADRILLA no.2 ALBAÑILERIA (0.2 DE CABO DE OF. + 1 OF. ALBAÑIL + 1 AY. OFICIALES) | G13: UNIDAD | H13: JORNAL
G14: CANTIDAD | H14: 1
A15: MATERIALES
A16: DESCRIPCIÓN | E16: UNIDAD | F16: Pm | G16: Cm | H16: M=Pm x Cm
F28: SUMA 1 | H28: =SUM(H17:H27) -> 0
A29: MANO DE OBRA
A30: CATEGORÍA | C30: UNIDAD | D30: SALARIO (a) | E30: CANT (b) | F30: Sr=(a) x (b) | G30: R | H30: Mo = Sr / R
A31: =Salarios!C11 -> CABO DE OFICIO | C31: jor | D31: =Salarios!F11 -> 1063.3376 | E31: =2/10 -> 0.2 | F31: =+D31*E31 -> 212.66752 | G31: 1 | H31: =F31/G31 -> 212.66752
A32: =Salarios!C10 -> OFICIAL ALBAÑIL | C32: jor | D32: =Salarios!F9 -> 690.62582 | E32: 1 | F32: =+D32*E32 -> 690.62582 | G32: 1 | H32: =F32/G32 -> 690.62582
A33: =Salarios!C6 -> AYUDANTE OFICIAL | C33: jor | D33: =Salarios!F6 -> 621.96791 | E33: 1 | F33: =+D33*E33 -> 621.96791 | G33: 1 | H33: =F33/G33 -> 621.96791
F34: SUMA 2 | H34: =SUM(H31:H33) -> 1525.2613
A35: MAQUINARIA Y EQUIPO DE CONSTRUCCIÓN
A36: DESCRIPCIÓN | E36: UNIDAD | F36: Phm | G36: Rhm | H36: ME = Phm / Rhm
F41: SUMA 3 | H41: =SUM(H37:H40) -> 0
A42: HERRAMIENTA Y EQUIPO DE SEGURIDAD
A43: Herramienta de mano | F43: Kh | G43: Mo | H43: Hm = Kh X Mo
H44: =+F44*G44 -> 0
A45: Equipo de seguridad | F45: Ks | G45: Mo | H45: Es = Ks X Mo
H46: =+F46*G46 -> 0
F47: SUMA 4 | H47: =+H44+H46 -> 0
A48: (CD) COSTO DIRECTO (Suma 1 + 2 + 3 + 4) | H48: =+H28+H34+H41+H47 -> 1525.2613

Sheet CUADR 3
C2: LICITACIÓN | H2: ANEXO
C4: PARA: | D4: =Catalogo!E3 -> OBRA, MANTENIMIENTO A UNIDADES 1, 2 Y 4 DE LA C.T. EMILIO PORTES GIL INSTALACIÓN DE AISLAMIENTOS TÉRMICOS PARA EL PARO PROGRAMADO DEL AÑO 2026 | H4: 11
A6: NOMBRE O RAZÓN SOCIAL DEL LICITANTE: | D6: FIRMA DEL LICITANTE: | G6: SUBDIRECCIÓN DE:
A10: ANÁLISIS DE LOS PRECIOS UNITARIOS DE LOS CONCEPTOS DE TRABAJO DEL CATÁLOGO | H10: HOJA: 3
H11: DE 4
A13: =Catalogo!A12 -> 1 | B13: CONCEPTO: | C13: CUADRILLA no.3 AISLAMIENTOS (0.3 DE CABO DE OF 1 OF. AISLADOR + 2 AYUD OFICIAL.) | G13: UNIDAD | H13: JORNAL
G14: CANTIDAD | H14: 1
A15: MATERIALES
A16: DESCRIPCIÓN | E16: UNIDAD | F16: Pm | G16: Cm | H16: M=Pm x Cm
F28: SUMA 1 | H28: =SUM(H17:H27) -> 0
A29: MANO DE OBRA
A30: CATEGORÍA | C30: UNIDAD | D30: SALARIO (a) | E30: CANT (b) | F30: Sr=(a) x (b) | G30: R | H30: Mo = Sr / R
A31: =Salarios!C11 -> CABO DE OFICIO | C31: jor | D31: =Salarios!F11 -> 1063.3376 | E31: =3/10 -> 0.3 | F31: =+D31*E31 -> 319.00128 | G31: 1 | H31: =F31/G31 -> 319.00128
A32: =Salarios!C9 -> OFICIAL AISLADOR | C32: jor | D32: =Salarios!F9 -> 690.62582 | E32: 1 | F32: =+D32*E32 -> 690.62582 | G32: 1 | H32: =F32/G32 -> 690.62582
A33: =Salarios!C6 -> AYUDANTE OFICIAL | C33: jor | D33: =Salarios!F6 -> 621.96791 | E33: 2 | F33: =+D33*E33 -> 1243.9358 | G33: 1 | H33: =F33/G33 -> 1243.9358
F34: SUMA 2 | H34: =SUM(H31:H33) -> 2253.5629
A35: MAQUINARIA Y EQUIPO DE CONSTRUCCIÓN
A36: DESCRIPCIÓN | E36: UNIDAD | F36: Phm | G36: Rhm | H36: ME = Phm / Rhm
F41: SUMA 3 | H41: =SUM(H37:H40) -> 0
A42: HERRAMIENTA Y EQUIPO DE SEGURIDAD
A43: Herramienta de mano | F43: Kh | G43: Mo | H43: Hm = Kh X Mo
A45: Equipo de seguridad | F45: Ks | G45: Mo | H45: Es = Ks X Mo
F47: SUMA 4 | H47: =+H44+H46 -> 0
A48: (CD) COSTO DIRECTO (Suma 1 + 2 + 3 + 4) | H48: =+H28+H34+H41+H47 -> 2253.5629

Sheet CUADR 4
C2: LICITACIÓN | H2: ANEXO
C4: PARA: | D4: =Catalogo!E3 -> OBRA, MANTENIMIENTO A UNIDADES 1, 2 Y 4 DE LA C.T. EMILIO PORTES GIL INSTALACIÓN DE AISLAMIENTOS TÉRMICOS PARA EL PARO PROGRAMADO DEL AÑO 2026 | H4: 11
A6: NOMBRE O RAZÓN SOCIAL DEL LICITANTE: | D6: FIRMA DEL LICITANTE: | G6: SUBDIRECCIÓN DE:
A10: ANÁLISIS DE LOS PRECIOS UNITARIOS DE LOS CONCEPTOS DE TRABAJO DEL CATÁLOGO | H10: HOJA: 4
H11: DE 4
A13: =Catalogo!A12 -> 1 | B13: CONCEPTO: | C13: CUADRILLA no.4 LAMINEROS (0.6 DE CABO DE OF 2 OF. LAMINEROS + 2 AYUD OFICIAL+ 2 AYUDANTES GENERALES.) | G13: UNIDAD | H13: JORNAL
G14: CANTIDAD | H14: 1
A15: MATERIALES
A16: DESCRIPCIÓN | E16: UNIDAD | F16: Pm | G16: Cm | H16: M=Pm x Cm
F28: SUMA 1 | H28: =SUM(H17:H27) -> 0
A29: MANO DE OBRA
A30: CATEGORÍA | C30: UNIDAD | D30: SALARIO (a) | E30: CANT (b) | F30: Sr=(a) x (b) | G30: R | H30: Mo = Sr / R
A31: =Salarios!C11 -> CABO DE OFICIO | C31: jor | D31: =Salarios!F11 -> 1063.3376 | E31: =6/10 -> 0.6 | F31: =+D31*E31 -> 638.00256 | G31: 1 | H31: =F31/G31 -> 638.00256
A32: =Salarios!C8 -> OFICIAL LAMINERO | C32: jor | D32: =Salarios!F8 -> 690.62582 | E32: 2 | F32: =+D32*E32 -> 1381.2516 | G32: 1 | H32: =F32/G32 -> 1381.2516
A33: =Salarios!C13 -> AYUDANTE GENERAL | C33: jor | D33: =Salarios!F13 -> 620.8315 | E33: 2 | F33: =+D33*E33 -> 1241.663 | G33: 1 | H33: =F33/G33 -> 1241.663
A34: =Salarios!C6 -> AYUDANTE OFICIAL | C34: jor | D34: =Salarios!F6 -> 621.96791 | E34: 2 | F34: =+D34*E34 -> 1243.9358 | G34: 1 | H34: =F34/G34 -> 1243.9358
F35: SUMA 2 | H35: =SUM(H31:H34) -> 4504.853
A36: MAQUINARIA Y EQUIPO DE CONSTRUCCIÓN
A37: DESCRIPCIÓN | E37: UNIDAD | F37: Phm | G37: Rhm | H37: ME = Phm / Rhm
F42: SUMA 3 | H42: =SUM(H38:H41) -> 0
A43: HERRAMIENTA Y EQUIPO DE SEGURIDAD
A44: Herramienta de mano | F44: Kh | G44: Mo | H44: Hm = Kh X Mo
A46: Equipo de seguridad | F46: Ks | G46: Mo | H46: Es = Ks X Mo
F48: SUMA 4 | H48: =+H45+H47 -> 0
A49: (CD) COSTO DIRECTO (Suma 1 + 2 + 3 + 4) | H49: =+H28+H35+H42+H48 -> 4504.853

Sheet EQUIPOS
C2: MATERIALES CONCURSO CFE-0700-CSCON-0040-2025 | F2: PORCENTAJE DE INFLACIÓN | G2: PRECIO FINAL
C3: MATERIAL | D3: UNIDAD | E3: C.H.
B4: 1 | C4: ANDAMIOS CON CANASTILLA Y GUINDOLA | D4: HORA | E4: 53.65 | F4: 0.0169 | G4: =((E4*F4)+E4) -> 54.556685
B5: 2 | C5: CAMION DOBLE RODADA CHEVROLET SILVERADO CON PLATAFORMA DE REDILAS CARGA HASTA 2 1/2 TON. | D5: HORA | E5: 557.99 | F5: 0.0169 | G5: =((E5*F5)+E5) -> 567.42003
B6: 3 | C6: BUFFER/PULIDOR DE DISCO DE 4 1/2 | D6: HORA | E6: 14.94 | F6: 0.0169 | G6: =((E6*F6)+E6) -> 15.192486
B7: 4 | C7: BISELADOR A DE LAMINA | D7: HORA | E7: 6.26 | F7: 0.0169 | G7: =((E7*F7)+E7) -> 6.365794

Sheet Materiales
B2: MATERIALES CONCURSO CFE-0700-CSCON-0040-2025 | E2: PORCENTAJE DE INFLACIÓN | F2: PRECIO FINAL
B3: MATERIAL | C3: UNIDAD | D3: PRECIO
A4: 1 | B4: ALMBRE GALVANIZADO CAL. 18 | C4: KG | D4: 95.58 | E4: 0.0169 | F4: =((D4*E4)+D4) -> 97.195302
A5: 2 | B5: PRIMARIO ANTICORROSIVO CFE-P34 | C5: L | D5: 385.89 | E5: 0.0169 | F5: =((D5*E5)+D5) -> 392.41154
A6: 3 | B6: SOLVENTE CATALIZADOR CFE-P34 | C6: L | D6: 120 | E6: 0.0169 | F6: =((D6*E6)+D6) -> 122.028
A7: 4 | B7: PIJAS DE ACERO INOX. DE 3/16 X 3/4 DE LARGO | C7: PZA | D7: 3.25 | E7: 0.0169 | F7: =((D7*E7)+D7) -> 3.304925
A8: 5 | B8: LAMINA LISA CAL. 24 | C8: M2 | D8: 175.25 | E8: 0.0169 | F8: =((D8*E8)+D8) -> 178.21173
A9: 6 | B9: MEDIAS CAÑAS DE FIBRA DE VIDRIO DE 2" ESPESOR CON BARRA DE VAPOR PARA TUBERÍAS DE 3/4" A 3 " DE DIAMETRO | C9: ML | D9: 342.15 | E9: 0.0169 | F9: =((D9*E9)+D9) -> 347.93233
A10: 7 | B10: BROCHA DE 2" | C10: PZA | D10: 62.5 | E10: 0.0169 | F10: =((D10*E10)+D10) -> 63.55625
A11: 8 | B11: MEDIAS CAÑAS DE FIBRA DE VIDRIO DE 2" ESPESOR CON BARRA DE VAPOR PARA TUBERÍAS DE 4" A 6 " DE DIAMETRO | C11: ML | D11: 621.36 | E11: 0.0169 | F11: =((D11*E11)+D11) -> 631.86098
A12: 9 | B12: COLCHA ARMADA DE LANA MINERAL DE 2´X8´X4" DE ESPESOR CON UNA DENSIDAD DE 12 LBR/PIES | C12: M2 | D12: 941.25 | E12: 0.0169 | F12: =((D12*E12)+D12) -> 957.15712
A13: 10 | B13: CEMENTO MONOLITICO | C13: KG | D13: 14.25 | E13: 0.0169 | F13: =((D13*E13)+D13) -> 14.490825
A14: 11 | B14: IMPERMEABILIZANTE HI MASTIC | C14: L | D14: 95.36 | E14: 0.0169 | F14: =((D14*E14)+D14) -> 96.971584
B16: MATERIALES COTIZACIÓN DEQUIMSA | F16: PRECIO FINAL
B17: MATERIAL | C17: UNIDAD | D17: PRECIO
A18: 12 | B18: P31 RECUBRIMIENTO PARA ALTAS TEMPERATURAS COLOR ALUMINIO | C18: L | D18: 638 | F18: =((D18*E18)+D18) -> 638
A19: 13 | B19: ADELGAZADOR PARA CFE-P31 | C19: L | D19: 100.2 | F19: =((D19*E19)+D19) -> 100.2

Sheet SOBRECOSTOS
A3: Compañía | B3: INDUSTREAM S.A. DE C.V. | C3: SERAMAQ S.A. DE C.V. | D3: URCOTAM S.A. DE C.V. | E3: PROMEDIO
A5: Concurso | B5: Concurso CFE-0700-CSCON-0040-2025 | C5: Concurso CFE-0700-CSCON-0031-2022 | D5: Concurso CFE-0600-CSCON-0008-2019
A6: Descripción del concurso | B6: Mantenimiento anual de la Unidad 3 aislamientos térmicos de la Central Termoeléctrica Emilio Portes Gil. | C6: (GT58) Obra de Aislamientos Térmico en caldera de la CT Emilio Portes Gil | D6: Recubrimiento a estructuras y equipos de las Unidades 1, 2 y 4 de la C.T. Presidente Emilio Portes Gil.
A8: Fecha | B8: 45915 | C8: 44638 | D8: 43538
A9: Costos indirectos | B9: 0.229466 | C9: 0.2489 | D9: 0.16 | E9: =(+B9+C9+D9)/3 -> 0.21278867
A10: Financiamiento | B10: 0.013405 | C10: 0.0112 | D10: 0.0071 | E10: =(+B10+C10+D10)/3 -> 0.010568333
A11: Utilidad | B11: 0.1 | C11: 0.08 | D11: 0.1 | E11: =(+B11+C11+D11)/3 -> 0.093333333
A12: Cargos adicionales | B12: 0.00839 | C12: 0.0096 | D12: 0.006026 | E12: =(+B12+C12+D12)/3 -> 0.0080053333
A13: Herramienta menor | B13: 0.05 | C13: 0.03 | D13: 0.03 | E13: =(+B13+C13+D13)/3 -> 0.036666667
A14: Equipo de seguridad | B14: 0.05 | C14: 0.03 | D14: 0.02 | E14: =(B14+C14+D14)/3 -> 0.033333333

Sheet Catalogo
D2: LICITACIÓN | M2: ANEXO
D3: NOMBRE DE LA OBRA: | E3: OBRA, MANTENIMIENTO A UNIDADES 1, 2 Y 4 DE LA C.T. EMILIO PORTES GIL INSTALACIÓN DE AISLAMIENTOS TÉRMICOS PARA EL PARO PROGRAMADO DEL AÑO 2026
A5: SUBDIRECCIÓN DE GENERACION | F5: NOMBRE O RAZÓN SOCIAL DEL LICITANTE | K5: FIRMA DEL LICITANTE
M6: HOJA
M8: DE
A9: CATÁLOGO DE CONCEPTOS DE TRABAJO CONTENIENDO EL IMPORTE TOTAL DE LA PROPUESTA
A10: No. | B10: ESPECIFICACIÓN | C10: DESCRIPCIÓN DE LA PARTIDA, | G10: CANTIDAD | H10: UNIDAD | I10: PRECIO UNITARIO | L10: IMPORTE
C11: SUBPARTIDAD O CONCEPTO | I11: CON NÚMERO | J11: CON LETRA | L11: PESOS
A12: 1 | B12: III-01 Y III-02 | C12: SUMINISTRO, RETIRO Y COLOCACIÓN DE AISLAMIENTO TÉRMICO Y LAMINA DE ALUMINIO LISA CAL. 24 EN TUBERÍAS DE LA UNIDAD 1 | O12: =G12 -> 0 | P12: 93.59 | Q12: =O12*P12 -> 0
A13: 1.1 | B13: III-01 | C13: SUMINISTRO, RETIRO Y COLOCACIÓN DE AISLAMIENTO TÉRMICO Y LAMINA DE ALUMINIO LISA CAL. 24 EN TUBERÍAS DESDE 3/4" HASTA 3"DE DIÁMETRO | G13: 100 | H13: ML | I13: =ROUND('PU 1.1'!H55,2) -> 1154.71 | J13: =[8]!NumLetras(L13) -> #NAME? | L13: =G13*I13 -> 115471 | O13: =G13 -> 100 | P13: 841.03 | Q13: =O13*P13 -> 84103
A14: 1.2 | B14: III-01 | C14: SUMINISTRO, RETIRO Y COLOCACIÓN DE AISLAMIENTO TÉRMICO Y LAMINA DE ALUMINIO LISA CAL. 24 EN TUBERÍAS DESDE 4" HASTA 6"DE DIÁMETRO | G14: 100 | H14: ML | I14: =ROUND('PU 1.2'!H55,2) -> 1616.84 | J14: =[8]!NumLetras(L14) -> #NAME? | L14: =G14*I14 -> 161684 | O14: =G14 -> 100 | P14: 196.99 | Q14: =O14*P14 -> 19699
A15: 1.3 | B15: III-02 | C15: SUMINISTRO, RETIRO Y COLOCACIÓN DE AISLAMIENTO TÉRMICO Y LAMINA DE ALUMINIO LISA CAL. 24 EN TUBERÍAS DESDE 8" HASTA 14"DE DIÁMETRO | G15: 100 | H15: ML | I15: =ROUND('PU 1.3'!H55,2) -> 2082.51 | J15: =[8]!NumLetras(L15) -> #NAME? | L15: =G15*I15 -> 208251 | O15: =G15 -> 100 | P15: 2256.09 | Q15: =O15*P15 -> 225609
A16: 2 | B16: III-03 | C16: SUMINISTRO, RETIRO Y COLOCACIÓN DE AISLAMIENTO TÉRMICO A VÁLVULAS UNIDAD 1 | O16: =G16 -> 0 | P16: 6537.25 | Q16: =O16*P16 -> 0
A17: 2.1 | B17: III-03 | C17: VÁLVULAS DE 4" | G17: 10 | H17: PZA | I17: =ROUND('PU 1.4'!H52,2) -> 1801.07 | J17: =[8]!NumLetras(L17) -> #NAME? | L17: =G17*I17 -> 18010.7
A18: 2.2 | B18: III-03 | C18: VÁLVULAS DE 6" | G18: 10 | H18: PZA | I18: =ROUND('PU 1.5'!H52,2) -> 1915.43 | J18: =[8]!NumLetras(L18) -> #NAME? | L18: =G18*I18 -> 19154.3
A19: 2.3 | B19: III-03 | C19: VÁLVULAS DE 8" | G19: 10 | H19: PZA | I19: =ROUND('PU 1.6'!H52,2) -> 2333.62 | J19: =[8]!NumLetras(L19) -> #NAME? | L19: =G19*I19 -> 23336.2
A20: 2.4 | B20: III-03 | C20: VÁLVULAS DE 10 A 14" | G20: 5 | H20: PZA | I20: =ROUND('PU 1.7'!H52,2) -> 2765.63 | J20: =[8]!NumLetras(L20) -> #NAME? | L20: =G20*I20 -> 13828.15
A21: 3 | B21: III-01 Y III-02 | C21: SUMINISTRO, RETIRO Y COLOCACIÓN DE AISLAMIENTO TÉRMICO Y LAMINA DE ALUMINIO LISA CAL. 24 EN TUBERÍAS DE LA UNIDAD 2
A22: 3.1 | B22: III-01 | C22: SUMINISTRO, RETIRO Y COLOCACIÓN DE AISLAMIENTO TÉRMICO Y LAMINA DE ALUMINIO LISA CAL. 24 EN TUBERÍAS DESDE 3/4" HASTA 3"DE DIÁMETRO | G22: 100 | H22: ML | I22: =ROUND('PU 1.1'!H55,2) -> 1154.71 | J22: =[8]!NumLetras(L22) -> #NAME? | L22: =G22*I22 -> 115471
A23: 3.2 | B23: III-01 | C23: SUMINISTRO, RETIRO Y COLOCACIÓN DE AISLAMIENTO TÉRMICO Y LAMINA DE ALUMINIO LISA CAL. 24 EN TUBERÍAS DESDE 4" HASTA 6"DE DIÁMETRO | G23: 100 | H23: ML | I23: =ROUND('PU 1.2'!H55,2) -> 1616.84 | J23: =[8]!NumLetras(L23) -> #NAME? | L23: =G23*I23 -> 161684
A24: 3.3 | B24: III-02 | C24: SUMINISTRO, RETIRO Y COLOCACIÓN DE AISLAMIENTO TÉRMICO Y LAMINA DE ALUMINIO LISA CAL. 24 EN TUBERÍAS DESDE 8" HASTA 14"DE DIÁMETRO | G24: 100 | H24: ML | I24: =ROUND('PU 1.3'!H55,2) -> 2082.51 | J24: =[8]!NumLetras(L24) -> #NAME? | L24: =G24*I24 -> 208251
A25: 4 | B25: III-03 | C25: SUMINISTRO, RETIRO Y COLOCACIÓN DE AISLAMIENTO TÉRMICO A VÁLVULAS UNIDAD 2
A26: 4.1 | B26: III-03 | C26: VÁLVULAS DE 4" | G26: 10 | H26: PZA | I26: =ROUND('PU 1.4'!H52,2) -> 1801.07 | J26: =[8]!NumLetras(L26) -> #NAME? | L26: =G26*I26 -> 18010.7
A27: 4.2 | B27: III-03 | C27: VÁLVULAS DE 6" | G27: 10 | H27: PZA | I27: =ROUND('PU 1.5'!H52,2) -> 1915.43 | J27: =[8]!NumLetras(L27) -> #NAME? | L27: =G27*I27 -> 19154.3
A28: 4.3 | B28: III-03 | C28: VÁLVULAS DE 8" | G28: 10 | H28: PZA | I28: =ROUND('PU 1.6'!H52,2) -> 2333.62 | J28: =[8]!NumLetras(L28) -> #NAME? | L28: =G28*I28 -> 23336.2
A29: 4.4 | B29: III-03 | C29: VÁLVULAS DE 10 A 14" | G29: 5 | H29: PZA | I29: =ROUND('PU 1.7'!H52,2) -> 2765.63 | J29: =[8]!NumLetras(L29) -> #NAME? | L29: =G29*I29 -> 13828.15
A30: 5 | B30: III-01 Y III-02 | C30: SUMINISTRO, RETIRO Y COLOCACIÓN DE AISLAMIENTO TÉRMICO Y LAMINA DE ALUMINIO LISA CAL. 24 EN TUBERÍAS DE LA UNIDAD 4
A31: 5.1 | B31: III-01 | C31: SUMINISTRO, RETIRO Y COLOCACIÓN DE AISLAMIENTO TÉRMICO Y LAMINA DE ALUMINIO LISA CAL. 24 EN TUBERÍAS DESDE 3/4" HASTA 3"DE DIÁMETRO | G31: 200 | H31: ML | I31: =ROUND('PU 1.1'!H55,2) -> 1154.71 | J31: =[8]!NumLetras(L31) -> #NAME? | L31: =G31*I31 -> 230942
A32: 5.2 | B32: III-01 | C32: SUMINISTRO, RETIRO Y COLOCACIÓN DE AISLAMIENTO TÉRMICO Y LAMINA DE ALUMINIO LISA CAL. 24 EN TUBERÍAS DESDE 4" HASTA 6"DE DIÁMETRO | G32: 150 | H32: ML | I32: =ROUND('PU 1.2'!H55,2) -> 1616.84 | J32: =[8]!NumLetras(L32) -> #NAME? | L32: =G32*I32 -> 242526
A33: 5.3 | B33: III-02 | C33: SUMINISTRO, RETIRO Y COLOCACIÓN DE AISLAMIENTO TÉRMICO Y LAMINA DE ALUMINIO LISA CAL. 24 EN TUBERÍAS DESDE 8" HASTA 14"DE DIÁMETRO | G33: 150 | H33: ML | I33: =ROUND('PU 1.3'!H55,2) -> 2082.51 | J33: =[8]!NumLetras(L33) -> #NAME? | L33: =G33*I33 -> 312376.5
A34: 6 | B34: III-03 | C34: SUMINISTRO, RETIRO Y COLOCACIÓN DE AISLAMIENTO TÉRMICO A VÁLVULAS UNIDAD 4
A35: 6.1 | B35: III-03 | C35: VÁLVULAS DE 4" | G35: 10 | H35: PZA | I35: =ROUND('PU 1.4'!H52,2) -> 1801.07 | J35: =[8]!NumLetras(L35) -> #NAME? | L35: =G35*I35 -> 18010.7
A36: 6.2 | B36: III-03 | C36: VÁLVULAS DE 6" | G36: 10 | H36: PZA | I36: =ROUND('PU 1.5'!H52,2) -> 1915.43 | J36: =[8]!NumLetras(L36) -> #NAME? | L36: =G36*I36 -> 19154.3
A37: 6.3 | B37: III-03 | C37: VÁLVULAS DE 8" | G37: 10 | H37: PZA | I37: =ROUND('PU 1.6'!H52,2) -> 2333.62 | J37: =[8]!NumLetras(L37) -> #NAME? | L37: =G37*I37 -> 23336.2
A38: 6.4 | B38: III-03 | C38: VÁLVULAS DE 10 A 14" | G38: 5 | H38: PZA | I38: =ROUND('PU 1.7'!H52,2) -> 2765.63 | J38: =[8]!NumLetras(L38) -> #NAME? | L38: =G38*I38 -> 13828.15
J39: IMPORTE DE ESTA HOJA | L39: =SUM(L13:M38) -> 1979644.5 | Q39: =SUM(Q12:Q38) -> 329411
J40: IMPORTE ACUMULADO HASTA LA HOJA ANTERIOR | L40: 0
J41: IMPORTE ACUMULADO HASTA ESTA HOJA | L41: =+L39+L40 -> 1979644.5 | Q41: 6623.62
J42: IMPORTE TOTAL DE LA PROPUESTA | L42: =+L41 -> 1979644.5
K50: ER

Sheet PU 1.1
C2: LICITACIÓN | H2: ANEXO
C4: PARA: | D4: =Catalogo!E3 -> OBRA, MANTENIMIENTO A UNIDADES 1, 2 Y 4 DE LA C.T. EMILIO PORTES GIL INSTALACIÓN DE AISLAMIENTOS TÉRMICOS PARA EL PARO PROGRAMADO DEL AÑO 2026 | H4: 11
A6: NOMBRE O RAZÓN SOCIAL DEL LICITANTE: | D6: FIRMA DEL LICITANTE: | G6: SUBDIRECCIÓN DE:
A10: ANÁLISIS DE LOS PRECIOS UNITARIOS DE LOS CONCEPTOS DE TRABAJO DEL CATÁLOGO | H10: HOJA: 1
H11: DE 7
A13: 1.1, 3.1 Y 5.1 | B13: CONCEPTO: | C13: SUMINISTRO, RETIRO Y COLOCACIÓN DE AISLAMIENTO TÉRMICO Y LAMINA DE ALUMINIO LISA CAL. 24 EN TUBERÍAS DESDE 3/4" HASTA 3"DE DIÁMETRO | G13: UNIDAD | H13: ML
A14: III-01 | G14: CANTIDAD
A15: MATERIALES
A16: DESCRIPCIÓN | E16: UNIDAD | F16: Pm | G16: Cm | H16: M=Pm x Cm
A17: =Materiales!B4 -> ALMBRE GALVANIZADO CAL. 18 | E17: =Materiales!C4 -> KG | F17: =Materiales!F4 -> 97.195302 | G17: 0.012 | H17: =+F17*G17 -> 1.1663436
A18: =Materiales!B5 -> PRIMARIO ANTICORROSIVO CFE-P34 | E18: =Materiales!C5 -> L | F18: =Materiales!F5 -> 392.41154 | G18: 0.06 | H18: =+F18*G18 -> 23.544692
A19: =Materiales!B6 -> SOLVENTE CATALIZADOR CFE-P34 | E19: =Materiales!C6 -> L | F19: =Materiales!F6 -> 122.028 | G19: 0.04 | H19: =+F19*G19 -> 4.88112
A20: =Materiales!B7 -> PIJAS DE ACERO INOX. DE 3/16 X 3/4 DE LARGO | E20: =Materiales!C7 -> PZA | F20: =Materiales!F7 -> 3.304925 | G20: 10 | H20: =+F20*G20 -> 33.04925
A21: =Materiales!B8 -> LAMINA LISA CAL. 24 | E21: =Materiales!C8 -> M2 | F21: =Materiales!F8 -> 178.21173 | G21: 0.55 | H21: =+F21*G21 -> 98.016449
A22: =Materiales!B9 -> MEDIAS CAÑAS DE FIBRA DE VIDRIO DE 2" ESPESOR CON BARRA DE VAPOR PARA TUBERÍAS DE 3/4" A 3 " DE DIAMETRO | E22: =Materiales!C9 -> ML | F22: =Materiales!F9 -> 347.93233 | G22: 1 | H22: =+F22*G22 -> 347.93233
A23: =Materiales!B10 -> BROCHA DE 2" | E23: =Materiales!C10 -> PZA | F23: =Materiales!F10 -> 63.55625 | G23: 0.1 | H23: =+F23*G23 -> 6.355625
F27: SUMA 1 | H27: =SUM(H17:H26) -> 514.94581
A28: MANO DE OBRA
A29: CATEGORÍA | C29: UNIDAD | D29: SALARIO (a) | E29: CANT (b) | F29: Sr=(a) x (b) | G29: R | H29: Mo = Sr / R
A30: ='CUADR 1'!C13 -> CUADRILLA no.1 PINTURA (0.2 DE CABO DE OF. + 1 OF. PINTORES + 1 AYUD. OFICIAL ) | C30: jor | D30: ='CUADR 1'!H48 -> 1525.2613 | E30: 1 | F30: =+D30*E30 -> 1525.2613 | G30: 44 | H30: =F30/G30 -> 34.665028
A31: ='CUADR 4'!C13 -> CUADRILLA no.4 LAMINEROS (0.6 DE CABO DE OF 2 OF. LAMINEROS + 2 AYUD OFICIAL+ 2 AYUDANTES GENERALES.) | C31: jor | D31: ='CUADR 4'!H49 -> 4504.853 | E31: 1 | F31: =+D31*E31 -> 4504.853 | G31: 26 | H31: =F31/G31 -> 173.26358
A32: ='CUADR 3'!C13 -> CUADRILLA no.3 AISLAMIENTOS (0.3 DE CABO DE OF 1 OF. AISLADOR + 2 AYUD OFICIAL.) | C32: jor | D32: ='CUADR 3'!H48 -> 2253.5629 | E32: 1 | F32: =+D32*E32 -> 2253.5629 | G32: 34 | H32: =F32/G32 -> 66.281262
F33: SUMA 2 | H33: =SUM(H30:H32) -> 274.20987
A34: MAQUINARIA Y EQUIPO DE CONSTRUCCIÓN
A35: DESCRIPCIÓN | E35: UNIDAD | F35: Phm | G35: Rhm | H35: ME = Phm / Rhm
A36: =EQUIPOS!C4 -> ANDAMIOS CON CANASTILLA Y GUINDOLA | E36: =EQUIPOS!D4 -> HORA | F36: =EQUIPOS!G4 -> 54.556685 | G36: 2 | H36: =F36/G36 -> 27.278343
A37: =EQUIPOS!C5 -> CAMION DOBLE RODADA CHEVROLET SILVERADO CON PLATAFORMA DE REDILAS CARGA HASTA 2 1/2 TON. | E37: =EQUIPOS!D5 -> HORA | F37: =EQUIPOS!G5 -> 567.42003 | G37: 36 | H37: =F37/G37 -> 15.761668
A38: =EQUIPOS!C6 -> BUFFER/PULIDOR DE DISCO DE 4 1/2 | E38: =EQUIPOS!D6 -> HORA | F38: =EQUIPOS!G6 -> 15.192486 | G38: 5 | H38: =F38/G38 -> 3.0384972
A39: =EQUIPOS!C7 -> BISELADOR A DE LAMINA | E39: =EQUIPOS!D7 -> HORA | F39: =EQUIPOS!G7 -> 6.365794 | G39: 14 | H39: =F39/G39 -> 0.45469957
F40: SUMA 3 | H40: =SUM(H36:H39) -> 46.533207
A41: HERRAMIENTA Y EQUIPO DE SEGURIDAD
A42: Herramienta de mano | F42: Kh | G42: Mo | H42: Hm = Kh X Mo
F43: =SOBRECOSTOS!E13 -> 0.036666667 | G43: =+H33 -> 274.20987 | H43: =+F43*G43 -> 10.054362
A44: Equipo de seguridad | F44: Ks | G44: Mo | H44: Es = Ks X Mo
F45: =SOBRECOSTOS!E14 -> 0.033333333 | G45: =+H33 -> 274.20987 | H45: =+F45*G45 -> 9.140329
F46: SUMA 4 | H46: =+H43+H45 -> 19.194691
A47: (CD) COSTO DIRECTO (Suma 1 + 2 + 3 + 4) | H47: =+H27+H33+H40+H46 -> 854.88358
A49: COSTOS Y CARGOS UNITARIOS | G49: PORCENTAJE | H49: IMPORTE
A50: (CI) COSTO INDIRECTO = I (CD) | G50: =SOBRECOSTOS!E9 -> 0.21278867 | H50: =+G50*H47 -> 181.90954
A51: (CF) COSTO POR FINANCIAMIENTO = F (CD + CI) | G51: =SOBRECOSTOS!E10 -> 0.010568333 | H51: =(H47+H50)*G51 -> 10.957175
...

Sheet PU 1.2
C2: LICITACIÓN | H2: ANEXO
C4: PARA: | D4: =Catalogo!E3 -> OBRA, MANTENIMIENTO A UNIDADES 1, 2 Y 4 DE LA C.T. EMILIO PORTES GIL INSTALACIÓN DE AISLAMIENTOS TÉRMICOS PARA EL PARO PROGRAMADO DEL AÑO 2026 | H4: 11
A6: NOMBRE O RAZÓN SOCIAL DEL LICITANTE: | D6: FIRMA DEL LICITANTE: | G6: SUBDIRECCIÓN DE:
A10: ANÁLISIS DE LOS PRECIOS UNITARIOS DE LOS CONCEPTOS DE TRABAJO DEL CATÁLOGO | H10: HOJA: 2
H11: DE 7
A13: 1.2, 3.2 Y 5.2 | B13: CONCEPTO: | C13: SUMINISTRO, RETIRO Y COLOCACIÓN DE AISLAMIENTO TÉRMICO Y LAMINA DE ALUMINIO LISA CAL. 24 EN TUBERÍAS DESDE 4" HASTA 6"DE DIÁMETRO | G13: UNIDAD | H13: ML
A14: III-01 | G14: CANTIDAD
A15: MATERIALES
A16: DESCRIPCIÓN | E16: UNIDAD | F16: Pm | G16: Cm | H16: M=Pm x Cm
A17: =Materiales!B4 -> ALMBRE GALVANIZADO CAL. 18 | E17: =Materiales!C4 -> KG | F17: =Materiales!F4 -> 97.195302 | G17: 0.022 | H17: =+F17*G17 -> 2.1382966
A18: =Materiales!B5 -> PRIMARIO ANTICORROSIVO CFE-P34 | E18: =Materiales!C5 -> L | F18: =Materiales!F5 -> 392.41154 | G18: 0.08 | H18: =+F18*G18 -> 31.392923
A19: =Materiales!B6 -> SOLVENTE CATALIZADOR CFE-P34 | E19: =Materiales!C6 -> L | F19: =Materiales!F6 -> 122.028 | G19: 0.06 | H19: =+F19*G19 -> 7.32168
A20: =Materiales!B7 -> PIJAS DE ACERO INOX. DE 3/16 X 3/4 DE LARGO | E20: =Materiales!C7 -> PZA | F20: =Materiales!F7 -> 3.304925 | G20: 10 | H20: =+F20*G20 -> 33.04925
A21: =Materiales!B8 -> LAMINA LISA CAL. 24 | E21: =Materiales!C8 -> M2 | F21: =Materiales!F8 -> 178.21173 | G21: 0.55 | H21: =+F21*G21 -> 98.016449
A22: =Materiales!B11 -> MEDIAS CAÑAS DE FIBRA DE VIDRIO DE 2" ESPESOR CON BARRA DE VAPOR PARA TUBERÍAS DE 4" A 6 " DE DIAMETRO | E22: =Materiales!C11 -> ML | F22: =Materiales!F11 -> 631.86098 | G22: 1 | H22: =+F22*G22 -> 631.86098
A23: =Materiales!B10 -> BROCHA DE 2" | E23: =Materiales!C10 -> PZA | F23: =Materiales!F10 -> 63.55625 | G23: 0.1 | H23: =+F23*G23 -> 6.355625
F27: SUMA 1 | H27: =SUM(H17:H26) -> 810.13521
A28: MANO DE OBRA
A29: CATEGORÍA | C29: UNIDAD | D29: SALARIO (a) | E29: CANT (b) | F29: Sr=(a) x (b) | G29: R | H29: Mo = Sr / R
A30: ='CUADR 1'!C13 -> CUADRILLA no.1 PINTURA (0.2 DE CABO DE OF. + 1 OF. PINTORES + 1 AYUD. OFICIAL ) | C30: jor | D30: ='CUADR 1'!H48 -> 1525.2613 | E30: 1 | F30: =+D30*E30 -> 1525.2613 | G30: 40 | H30: =F30/G30 -> 38.131531
A31: ='CUADR 4'!C13 -> CUADRILLA no.4 LAMINEROS (0.6 DE CABO DE OF 2 OF. LAMINEROS + 2 AYUD OFICIAL+ 2 AYUDANTES GENERALES.) | C31: jor | D31: ='CUADR 4'!H49 -> 4504.853 | E31: 1 | F31: =+D31*E31 -> 4504.853 | G31: 22 | H31: =F31/G31 -> 204.76605
A32: ='CUADR 3'!C13 -> CUADRILLA no.3 AISLAMIENTOS (0.3 DE CABO DE OF 1 OF. AISLADOR + 2 AYUD OFICIAL.) | C32: jor | D32: ='CUADR 3'!H48 -> 2253.5629 | E32: 1 | F32: =+D32*E32 -> 2253.5629 | G32: 30 | H32: =F32/G32 -> 75.118764
F33: SUMA 2 | H33: =SUM(H30:H32) -> 318.01634
A34: MAQUINARIA Y EQUIPO DE CONSTRUCCIÓN
A35: DESCRIPCIÓN | E35: UNIDAD | F35: Phm | G35: Rhm | H35: ME = Phm / Rhm
A36: =EQUIPOS!C4 -> ANDAMIOS CON CANASTILLA Y GUINDOLA | E36: =EQUIPOS!D4 -> HORA | F36: =EQUIPOS!G4 -> 54.556685 | G36: 2 | H36: =F36/G36 -> 27.278343
A37: =EQUIPOS!C5 -> CAMION DOBLE RODADA CHEVROLET SILVERADO CON PLATAFORMA DE REDILAS CARGA HASTA 2 1/2 TON. | E37: =EQUIPOS!D5 -> HORA | F37: =EQUIPOS!G5 -> 567.42003 | G37: 36 | H37: =F37/G37 -> 15.761668
A38: =EQUIPOS!C6 -> BUFFER/PULIDOR DE DISCO DE 4 1/2 | E38: =EQUIPOS!D6 -> HORA | F38: =EQUIPOS!G6 -> 15.192486 | G38: 5 | H38: =F38/G38 -> 3.0384972
A39: =EQUIPOS!C7 -> BISELADOR A DE LAMINA | E39: =EQUIPOS!D7 -> HORA | F39: =EQUIPOS!G7 -> 6.365794 | G39: 12 | H39: =F39/G39 -> 0.53048283
F40: SUMA 3 | H40: =SUM(H36:H39) -> 46.60899
A41: HERRAMIENTA Y EQUIPO DE SEGURIDAD
A42: Herramienta de mano | F42: Kh | G42: Mo | H42: Hm = Kh X Mo
F43: =SOBRECOSTOS!E13 -> 0.036666667 | G43: =+H33 -> 318.01634 | H43: =+F43*G43 -> 11.660599
A44: Equipo de seguridad | F44: Ks | G44: Mo | H44: Es = Ks X Mo
F45: =SOBRECOSTOS!E14 -> 0.033333333 | G45: =+H33 -> 318.01634 | H45: =+F45*G45 -> 10.600545
F46: SUMA 4 | H46: =+H43+H45 -> 22.261144
A47: (CD) COSTO DIRECTO (Suma 1 + 2 + 3 + 4) | H47: =+H27+H33+H40+H46 -> 1197.0217
A49: COSTOS Y CARGOS UNITARIOS | G49: PORCENTAJE | H49: IMPORTE
A50: (CI) COSTO INDIRECTO = I (CD) | G50: =SOBRECOSTOS!E9 -> 0.21278867 | H50: =+G50*H47 -> 254.71265
A51: (CF) COSTO POR FINANCIAMIENTO = F (CD + CI) | G51: =SOBRECOSTOS!E10 -> 0.010568333 | H51: =(H47+H50)*G51 -> 15.342412
...

Sheet PU 1.3
C2: LICITACIÓN | H2: ANEXO
C4: PARA: | D4: =Catalogo!E3 -> OBRA, MANTENIMIENTO A UNIDADES 1, 2 Y 4 DE LA C.T. EMILIO PORTES GIL INSTALACIÓN DE AISLAMIENTOS TÉRMICOS PARA EL PARO PROGRAMADO DEL AÑO 2026 | H4: 11
A6: NOMBRE O RAZÓN SOCIAL DEL LICITANTE: | D6: FIRMA DEL LICITANTE: | G6: SUBDIRECCIÓN DE:
A10: ANÁLISIS DE LOS PRECIOS UNITARIOS DE LOS CONCEPTOS DE TRABAJO DEL CATÁLOGO | H10: HOJA: 3
H11: DE 7
A13: 1.3, 3.3 Y 5.3 | B13: CONCEPTO: | C13: SUMINISTRO, RETIRO Y COLOCACIÓN DE AISLAMIENTO TÉRMICO Y LAMINA DE ALUMINIO LISA CAL. 24 EN TUBERÍAS DESDE 8" HASTA 14"DE DIÁMETRO | G13: UNIDAD | H13: ML
A14: III-02 | G14: CANTIDAD
A15: MATERIALES
A16: DESCRIPCIÓN | E16: UNIDAD | F16: Pm | G16: Cm | H16: M=Pm x Cm
A17: =Materiales!B4 -> ALMBRE GALVANIZADO CAL. 18 | E17: =Materiales!C4 -> KG | F17: =Materiales!F4 -> 97.195302 | G17: 0.044 | H17: =+F17*G17 -> 4.2765933
A18: =Materiales!B5 -> PRIMARIO ANTICORROSIVO CFE-P34 | E18: =Materiales!C5 -> L | F18: =Materiales!F5 -> 392.41154 | G18: 0.2 | H18: =+F18*G18 -> 78.482308
A19: =Materiales!B6 -> SOLVENTE CATALIZADOR CFE-P34 | E19: =Materiales!C6 -> L | F19: =Materiales!F6 -> 122.028 | G19: 0.09 | H19: =+F19*G19 -> 10.98252
A20: =Materiales!B7 -> PIJAS DE ACERO INOX. DE 3/16 X 3/4 DE LARGO | E20: =Materiales!C7 -> PZA | F20: =Materiales!F7 -> 3.304925 | G20: 10 | H20: =+F20*G20 -> 33.04925
A21: =Materiales!B8 -> LAMINA LISA CAL. 24 | E21: =Materiales!C8 -> M2 | F21: =Materiales!F8 -> 178.21173 | G21: 0.8 | H21: =+F21*G21 -> 142.56938
A22: =Materiales!B12 -> COLCHA ARMADA DE LANA MINERAL DE 2´X8´X4" DE ESPESOR CON UNA DENSIDAD DE 12 LBR/PIES | E22: =Materiales!C12 -> M2 | F22: =Materiales!F12 -> 957.15712 | G22: 0.85 | H22: =+F22*G22 -> 813.58356
A23: =Materiales!B10 -> BROCHA DE 2" | E23: =Materiales!C10 -> PZA | F23: =Materiales!F10 -> 63.55625 | G23: 0.1 | H23: =+F23*G23 -> 6.355625
F27: SUMA 1 | H27: =SUM(H17:H26) -> 1089.2992
A28: MANO DE OBRA
A29: CATEGORÍA | C29: UNIDAD | D29: SALARIO (a) | E29: CANT (b) | F29: Sr=(a) x (b) | G29: R | H29: Mo = Sr / R
A30: ='CUADR 1'!C13 -> CUADRILLA no.1 PINTURA (0.2 DE CABO DE OF. + 1 OF. PINTORES + 1 AYUD. OFICIAL ) | C30: jor | D30: ='CUADR 1'!H48 -> 1525.2613 | E30: 1 | F30: =+D30*E30 -> 1525.2613 | G30: 36 | H30: =F30/G30 -> 42.368368
A31: ='CUADR 4'!C13 -> CUADRILLA no.4 LAMINEROS (0.6 DE CABO DE OF 2 OF. LAMINEROS + 2 AYUD OFICIAL+ 2 AYUDANTES GENERALES.) | C31: jor | D31: ='CUADR 4'!H49 -> 4504.853 | E31: 1 | F31: =+D31*E31 -> 4504.853 | G31: 18 | H31: =F31/G31 -> 250.26961
A32: ='CUADR 3'!C13 -> CUADRILLA no.3 AISLAMIENTOS (0.3 DE CABO DE OF 1 OF. AISLADOR + 2 AYUD OFICIAL.) | C32: jor | D32: ='CUADR 3'!H48 -> 2253.5629 | E32: 1 | F32: =+D32*E32 -> 2253.5629 | G32: 26 | H32: =F32/G32 -> 86.675497
F33: SUMA 2 | H33: =SUM(H30:H32) -> 379.31348
A34: MAQUINARIA Y EQUIPO DE CONSTRUCCIÓN
A35: DESCRIPCIÓN | E35: UNIDAD | F35: Phm | G35: Rhm | H35: ME = Phm / Rhm
A36: =EQUIPOS!C4 -> ANDAMIOS CON CANASTILLA Y GUINDOLA | E36: =EQUIPOS!D4 -> HORA | F36: =EQUIPOS!G4 -> 54.556685 | G36: 2 | H36: =F36/G36 -> 27.278343
A37: =EQUIPOS!C5 -> CAMION DOBLE RODADA CHEVROLET SILVERADO CON PLATAFORMA DE REDILAS CARGA HASTA 2 1/2 TON. | E37: =EQUIPOS!D5 -> HORA | F37: =EQUIPOS!G5 -> 567.42003 | G37: 36 | H37: =F37/G37 -> 15.761668
A38: =EQUIPOS!C6 -> BUFFER/PULIDOR DE DISCO DE 4 1/2 | E38: =EQUIPOS!D6 -> HORA | F38: =EQUIPOS!G6 -> 15.192486 | G38: 5 | H38: =F38/G38 -> 3.0384972
A39: =EQUIPOS!C7 -> BISELADOR A DE LAMINA | E39: =EQUIPOS!D7 -> HORA | F39: =EQUIPOS!G7 -> 6.365794 | G39: 12 | H39: =F39/G39 -> 0.53048283
F40: SUMA 3 | H40: =SUM(H36:H39) -> 46.60899
A41: HERRAMIENTA Y EQUIPO DE SEGURIDAD
A42: Herramienta de mano | F42: Kh | G42: Mo | H42: Hm = Kh X Mo
F43: =SOBRECOSTOS!E13 -> 0.036666667 | G43: =+H33 -> 379.31348 | H43: =+F43*G43 -> 13.908161
A44: Equipo de seguridad | F44: Ks | G44: Mo | H44: Es = Ks X Mo
F45: =SOBRECOSTOS!E14 -> 0.033333333 | G45: =+H33 -> 379.31348 | H45: =+F45*G45 -> 12.643783
F46: SUMA 4 | H46: =+H43+H45 -> 26.551943
A47: (CD) COSTO DIRECTO (Suma 1 + 2 + 3 + 4) | H47: =+H27+H33+H40+H46 -> 1541.7736
A49: COSTOS Y CARGOS UNITARIOS | G49: PORCENTAJE | H49: IMPORTE
A50: (CI) COSTO INDIRECTO = I (CD) | G50: =SOBRECOSTOS!E9 -> 0.21278867 | H50: =+G50*H47 -> 328.07196
A51: (CF) COSTO POR FINANCIAMIENTO = F (CD + CI) | G51: =SOBRECOSTOS!E10 -> 0.010568333 | H51: =(H47+H50)*G51 -> 19.761152
...

Sheet PU 1.4
C2: LICITACIÓN | H2: ANEXO
C4: PARA: | D4: =Catalogo!E3 -> OBRA, MANTENIMIENTO A UNIDADES 1, 2 Y 4 DE LA C.T. EMILIO PORTES GIL INSTALACIÓN DE AISLAMIENTOS TÉRMICOS PARA EL PARO PROGRAMADO DEL AÑO 2026 | H4: 11
A6: NOMBRE O RAZÓN SOCIAL DEL LICITANTE: | D6: FIRMA DEL LICITANTE: | G6: SUBDIRECCIÓN DE:
A10: ANÁLISIS DE LOS PRECIOS UNITARIOS DE LOS CONCEPTOS DE TRABAJO DEL CATÁLOGO | H10: HOJA: 4
H11: DE 7
A13: 2.1, 4.1 Y 6.1 | B13: CONCEPTO: | C13: SUMINISTRO, RETIRO Y COLOCACIÓN DE AISLAMIENTO TÉRMICO A VÁLVULAS DE 4" | G13: UNIDAD | H13: PZA
A14: III-03 | G14: CANTIDAD
A15: MATERIALES
A16: DESCRIPCIÓN | E16: UNIDAD | F16: Pm | G16: Cm | H16: M=Pm x Cm
A17: =Materiales!B4 -> ALMBRE GALVANIZADO CAL. 18 | E17: =Materiales!C4 -> KG | F17: =Materiales!F4 -> 97.195302 | G17: 0.016 | H17: =+F17*G17 -> 1.5551248
A18: =Materiales!B5 -> PRIMARIO ANTICORROSIVO CFE-P34 | E18: =Materiales!C5 -> L | F18: =Materiales!F5 -> 392.41154 | G18: 0.08 | H18: =+F18*G18 -> 31.392923
A19: =Materiales!B6 -> SOLVENTE CATALIZADOR CFE-P34 | E19: =Materiales!C6 -> L | F19: =Materiales!F6 -> 122.028 | G19: 0.03 | H19: =+F19*G19 -> 3.66084
A20: =Materiales!B10 -> BROCHA DE 2" | E20: =Materiales!C10 -> PZA | F20: =Materiales!F10 -> 63.55625 | G20: 0.1 | H20: =+F20*G20 -> 6.355625
A21: =Materiales!B12 -> COLCHA ARMADA DE LANA MINERAL DE 2´X8´X4" DE ESPESOR CON UNA DENSIDAD DE 12 LBR/PIES | E21: =Materiales!C12 -> M2 | F21: =Materiales!F12 -> 957.15712 | G21: 0.7 | H21: =+F21*G21 -> 670.00999
A22: =Materiales!B13 -> CEMENTO MONOLITICO | E22: =Materiales!C13 -> KG | F22: =Materiales!F13 -> 14.490825 | G22: 5 | H22: =+F22*G22 -> 72.454125
A23: =Materiales!B14 -> IMPERMEABILIZANTE HI MASTIC | E23: =Materiales!C14 -> L | F23: =Materiales!F14 -> 96.971584 | G23: 0.2 | H23: =+F23*G23 -> 19.394317
A24: =Materiales!B18 -> P31 RECUBRIMIENTO PARA ALTAS TEMPERATURAS COLOR ALUMINIO | E24: =Materiales!C18 -> L | F24: =Materiales!F18 -> 638 | G24: 0.35 | H24: =+F24*G24 -> 223.3
A25: =Materiales!B19 -> ADELGAZADOR PARA CFE-P31 | E25: =Materiales!C19 -> L | F25: =Materiales!F19 -> 100.2 | G25: 0.003 | H25: =+F25*G25 -> 0.3006
F26: SUMA 1 | H26: =SUM(H17:H25) -> 1028.4235
A27: MANO DE OBRA
A28: CATEGORÍA | C28: UNIDAD | D28: SALARIO (a) | E28: CANT (b) | F28: Sr=(a) x (b) | G28: R | H28: Mo = Sr / R
A29: ='CUADR 2'!C13 -> CUADRILLA no.2 ALBAÑILERIA (0.2 DE CABO DE OF. + 1 OF. ALBAÑIL + 1 AY. OFICIALES) | C29: jor | D29: ='CUADR 2'!H48 -> 1525.2613 | E29: 1 | F29: =D29*E29 -> 1525.2613 | G29: 20 | H29: =F29/G29 -> 76.263063
A30: ='CUADR 3'!C13 -> CUADRILLA no.3 AISLAMIENTOS (0.3 DE CABO DE OF 1 OF. AISLADOR + 2 AYUD OFICIAL.) | C30: jor | D30: ='CUADR 3'!H48 -> 2253.5629 | E30: 1 | F30: =D30*E30 -> 2253.5629 | G30: 20 | H30: =F30/G30 -> 112.67815
A31: ='CUADR 1'!C13 -> CUADRILLA no.1 PINTURA (0.2 DE CABO DE OF. + 1 OF. PINTORES + 1 AYUD. OFICIAL ) | C31: jor | D31: ='CUADR 1'!H48 -> 1525.2613 | E31: 1 | F31: =D31*E31 -> 1525.2613 | G31: 20 | H31: =F31/G31 -> 76.263063
F32: SUMA 2 | H32: =SUM(H29:H31) -> 265.20427
A33: MAQUINARIA Y EQUIPO DE CONSTRUCCIÓN
A34: DESCRIPCIÓN | E34: UNIDAD | F34: Phm | G34: Rhm | H34: ME = Phm / Rhm
A35: =EQUIPOS!C4 -> ANDAMIOS CON CANASTILLA Y GUINDOLA | E35: =EQUIPOS!D4 -> HORA | F35: =EQUIPOS!G4 -> 54.556685 | G35: 10 | H35: =F35/G35 -> 5.4556685
A36: =EQUIPOS!C5 -> CAMION DOBLE RODADA CHEVROLET SILVERADO CON PLATAFORMA DE REDILAS CARGA HASTA 2 1/2 TON. | E36: =EQUIPOS!D5 -> HORA | F36: =EQUIPOS!G5 -> 567.42003 | G36: 36 | H36: =F36/G36 -> 15.761668
F37: SUMA 3 | H37: =SUM(H35:H36) -> 21.217336
A38: HERRAMIENTA Y EQUIPO DE SEGURIDAD
A39: Herramienta de mano | F39: Kh | G39: Mo | H39: Hm = Kh X Mo
F40: =SOBRECOSTOS!E13 -> 0.036666667 | G40: =+H32 -> 265.20427 | H40: =+F40*G40 -> 9.7241566
A41: Equipo de seguridad | F41: Ks | G41: Mo | H41: Es = Ks X Mo
F42: =SOBRECOSTOS!E14 -> 0.033333333 | G42: =+H32 -> 265.20427 | H42: =+F42*G42 -> 8.8401424
F43: SUMA 4 | H43: =+H40+H42 -> 18.564299
A44: (CD) COSTO DIRECTO (Suma 1 + 2 + 3 + 4) | H44: =+H26+H32+H37+H43 -> 1333.4094
A46: COSTOS Y CARGOS UNITARIOS | G46: PORCENTAJE | H46: IMPORTE
A47: (CI) COSTO INDIRECTO = I (CD) | G47: =SOBRECOSTOS!E9 -> 0.21278867 | H47: =+G47*H44 -> 283.73442
A48: (CF) COSTO POR FINANCIAMIENTO = F (CD + CI) | G48: =SOBRECOSTOS!E10 -> 0.010568333 | H48: =(H44+H47)*G48 -> 17.090515
...

Sheet PU 1.5
C2: LICITACIÓN | H2: ANEXO
C4: PARA: | D4: =Catalogo!E3 -> OBRA, MANTENIMIENTO A UNIDADES 1, 2 Y 4 DE LA C.T. EMILIO PORTES GIL INSTALACIÓN DE AISLAMIENTOS TÉRMICOS PARA EL PARO PROGRAMADO DEL AÑO 2026 | H4: 11
A6: NOMBRE O RAZÓN SOCIAL DEL LICITANTE: | D6: FIRMA DEL LICITANTE: | G6: SUBDIRECCIÓN DE:
A10: ANÁLISIS DE LOS PRECIOS UNITARIOS DE LOS CONCEPTOS DE TRABAJO DEL CATÁLOGO | H10: HOJA: 5
H11: DE 7
A13: 2.2, 4.2 Y 6.2 | B13: CONCEPTO: | C13: SUMINISTRO, RETIRO Y COLOCACIÓN DE AISLAMIENTO TÉRMICO A VÁLVULAS DE 6" | G13: UNIDAD | H13: PZA
A14: III-03 | G14: CANTIDAD
A15: MATERIALES
A16: DESCRIPCIÓN | E16: UNIDAD | F16: Pm | G16: Cm | H16: M=Pm x Cm
A17: =Materiales!B4 -> ALMBRE GALVANIZADO CAL. 18 | E17: =Materiales!C4 -> KG | F17: =Materiales!F4 -> 97.195302 | G17: 0.022 | H17: =+F17*G17 -> 2.1382966
A18: =Materiales!B5 -> PRIMARIO ANTICORROSIVO CFE-P34 | E18: =Materiales!C5 -> L | F18: =Materiales!F5 -> 392.41154 | G18: 0.08 | H18: =+F18*G18 -> 31.392923
A19: =Materiales!B6 -> SOLVENTE CATALIZADOR CFE-P34 | E19: =Materiales!C6 -> L | F19: =Materiales!F6 -> 122.028 | G19: 0.06 | H19: =+F19*G19 -> 7.32168
A20: =Materiales!B10 -> BROCHA DE 2" | E20: =Materiales!C10 -> PZA | F20: =Materiales!F10 -> 63.55625 | G20: 0.1 | H20: =+F20*G20 -> 6.355625
A21: =Materiales!B12 -> COLCHA ARMADA DE LANA MINERAL DE 2´X8´X4" DE ESPESOR CON UNA DENSIDAD DE 12 LBR/PIES | E21: =Materiales!C12 -> M2 | F21: =Materiales!F12 -> 957.15712 | G21: 0.8 | H21: =+F21*G21 -> 765.7257
A22: =Materiales!B13 -> CEMENTO MONOLITICO | E22: =Materiales!C13 -> KG | F22: =Materiales!F13 -> 14.490825 | G22: 6 | H22: =+F22*G22 -> 86.94495
A23: =Materiales!B14 -> IMPERMEABILIZANTE HI MASTIC | E23: =Materiales!C14 -> L | F23: =Materiales!F14 -> 96.971584 | G23: 0.25 | H23: =+F23*G23 -> 24.242896
A24: =Materiales!B18 -> P31 RECUBRIMIENTO PARA ALTAS TEMPERATURAS COLOR ALUMINIO | E24: =Materiales!C18 -> L | F24: =Materiales!F18 -> 638 | G24: 0.2 | H24: =+F24*G24 -> 127.6
A25: =Materiales!B19 -> ADELGAZADOR PARA CFE-P31 | E25: =Materiales!C19 -> L | F25: =Materiales!F19 -> 100.2 | G25: 0.08 | H25: =+F25*G25 -> 8.016
F26: SUMA 1 | H26: =SUM(H17:H25) -> 1059.7381
A27: MANO DE OBRA
A28: CATEGORÍA | C28: UNIDAD | D28: SALARIO (a) | E28: CANT (b) | F28: Sr=(a) x (b) | G28: R | H28: Mo = Sr / R
A29: ='CUADR 2'!C13 -> CUADRILLA no.2 ALBAÑILERIA (0.2 DE CABO DE OF. + 1 OF. ALBAÑIL + 1 AY. OFICIALES) | C29: jor | D29: ='CUADR 2'!H48 -> 1525.2613 | E29: 1 | F29: =D29*E29 -> 1525.2613 | G29: 18 | H29: =F29/G29 -> 84.736736
A30: ='CUADR 3'!C13 -> CUADRILLA no.3 AISLAMIENTOS (0.3 DE CABO DE OF 1 OF. AISLADOR + 2 AYUD OFICIAL.) | C30: jor | D30: ='CUADR 3'!H48 -> 2253.5629 | E30: 1 | F30: =D30*E30 -> 2253.5629 | G30: 18 | H30: =F30/G30 -> 125.19794
A31: ='CUADR 1'!C13 -> CUADRILLA no.1 PINTURA (0.2 DE CABO DE OF. + 1 OF. PINTORES + 1 AYUD. OFICIAL ) | C31: jor | D31: ='CUADR 1'!H48 -> 1525.2613 | E31: 1 | F31: =D31*E31 -> 1525.2613 | G31: 18 | H31: =F31/G31 -> 84.736736
F32: SUMA 2 | H32: =SUM(H29:H31) -> 294.67141
A33: MAQUINARIA Y EQUIPO DE CONSTRUCCIÓN
A34: DESCRIPCIÓN | E34: UNIDAD | F34: Phm | G34: Rhm | H34: ME = Phm / Rhm
A35: =EQUIPOS!C4 -> ANDAMIOS CON CANASTILLA Y GUINDOLA | E35: =EQUIPOS!D4 -> HORA | F35: =EQUIPOS!G4 -> 54.556685 | G35: 2 | H35: =F35/G35 -> 27.278343
A36: =EQUIPOS!C5 -> CAMION DOBLE RODADA CHEVROLET SILVERADO CON PLATAFORMA DE REDILAS CARGA HASTA 2 1/2 TON. | E36: =EQUIPOS!D5 -> HORA | F36: =EQUIPOS!G5 -> 567.42003 | G36: 36 | H36: =F36/G36 -> 15.761668
F37: SUMA 3 | H37: =SUM(H35:H36) -> 43.04001
A38: HERRAMIENTA Y EQUIPO DE SEGURIDAD
A39: Herramienta de mano | F39: Kh | G39: Mo | H39: Hm = Kh X Mo
F40: =SOBRECOSTOS!E13 -> 0.036666667 | G40: =+H32 -> 294.67141 | H40: =+F40*G40 -> 10.804618
A41: Equipo de seguridad | F41: Ks | G41: Mo | H41: Es = Ks X Mo
F42: =SOBRECOSTOS!E14 -> 0.033333333 | G42: =+H32 -> 294.67141 | H42: =+F42*G42 -> 9.8223804
F43: SUMA 4 | H43: =+H40+H42 -> 20.626999
A44: (CD) COSTO DIRECTO (Suma 1 + 2 + 3 + 4) | H44: =+H26+H32+H37+H43 -> 1418.0765
A46: COSTOS Y CARGOS UNITARIOS | G46: PORCENTAJE | H46: IMPORTE
A47: (CI) COSTO INDIRECTO = I (CD) | G47: =SOBRECOSTOS!E9 -> 0.21278867 | H47: =+G47*H44 -> 301.75061
A48: (CF) COSTO POR FINANCIAMIENTO = F (CD + CI) | G48: =SOBRECOSTOS!E10 -> 0.010568333 | H48: =(H44+H47)*G48 -> 18.175706
...

Sheet PU 1.6
C2: LICITACIÓN | H2: ANEXO
C4: PARA: | D4: =Catalogo!E3 -> OBRA, MANTENIMIENTO A UNIDADES 1, 2 Y 4 DE LA C.T. EMILIO PORTES GIL INSTALACIÓN DE AISLAMIENTOS TÉRMICOS PARA EL PARO PROGRAMADO DEL AÑO 2026 | H4: 11
A6: NOMBRE O RAZÓN SOCIAL DEL LICITANTE: | D6: FIRMA DEL LICITANTE: | G6: SUBDIRECCIÓN DE:
A10: ANÁLISIS DE LOS PRECIOS UNITARIOS DE LOS CONCEPTOS DE TRABAJO DEL CATÁLOGO | H10: HOJA: 6
H11: DE 7
A13: 2.3, 4.3 Y 6.3 | B13: CONCEPTO: | C13: SUMINISTRO, RETIRO Y COLOCACIÓN DE AISLAMIENTO TÉRMICO A VÁLVULAS DE 8" | G13: UNIDAD | H13: PZA
A14: III-03 | G14: CANTIDAD
A15: MATERIALES
A16: DESCRIPCIÓN | E16: UNIDAD | F16: Pm | G16: Cm | H16: M=Pm x Cm
A17: =Materiales!B4 -> ALMBRE GALVANIZADO CAL. 18 | E17: =Materiales!C4 -> KG | F17: =Materiales!F4 -> 97.195302 | G17: 0.044 | H17: =+F17*G17 -> 4.2765933
A18: =Materiales!B5 -> PRIMARIO ANTICORROSIVO CFE-P34 | E18: =Materiales!C5 -> L | F18: =Materiales!F5 -> 392.41154 | G18: 0.12 | H18: =+F18*G18 -> 47.089385
A19: =Materiales!B6 -> SOLVENTE CATALIZADOR CFE-P34 | E19: =Materiales!C6 -> L | F19: =Materiales!F6 -> 122.028 | G19: 0.08 | H19: =+F19*G19 -> 9.76224
A20: =Materiales!B10 -> BROCHA DE 2" | E20: =Materiales!C10 -> PZA | F20: =Materiales!F10 -> 63.55625 | G20: 0.1 | H20: =+F20*G20 -> 6.355625
A21: =Materiales!B12 -> COLCHA ARMADA DE LANA MINERAL DE 2´X8´X4" DE ESPESOR CON UNA DENSIDAD DE 12 LBR/PIES | E21: =Materiales!C12 -> M2 | F21: =Materiales!F12 -> 957.15712 | G21: 1 | H21: =+F21*G21 -> 957.15712
A22: =Materiales!B13 -> CEMENTO MONOLITICO | E22: =Materiales!C13 -> KG | F22: =Materiales!F13 -> 14.490825 | G22: 7.5 | H22: =+F22*G22 -> 108.68119
A23: =Materiales!B14 -> IMPERMEABILIZANTE HI MASTIC | E23: =Materiales!C14 -> L | F23: =Materiales!F14 -> 96.971584 | G23: 0.3 | H23: =+F23*G23 -> 29.091475
A24: =Materiales!B18 -> P31 RECUBRIMIENTO PARA ALTAS TEMPERATURAS COLOR ALUMINIO | E24: =Materiales!C18 -> L | F24: =Materiales!F18 -> 638 | G24: 0.25 | H24: =+F24*G24 -> 159.5
A25: =Materiales!B19 -> ADELGAZADOR PARA CFE-P31 | E25: =Materiales!C19 -> L | F25: =Materiales!F19 -> 100.2 | G25: 0.08 | H25: =+F25*G25 -> 8.016
F26: SUMA 1 | H26: =SUM(H17:H25) -> 1329.9296
A27: MANO DE OBRA
A28: CATEGORÍA | C28: UNIDAD | D28: SALARIO (a) | E28: CANT (b) | F28: Sr=(a) x (b) | G28: R | H28: Mo = Sr / R
A29: ='CUADR 2'!C13 -> CUADRILLA no.2 ALBAÑILERIA (0.2 DE CABO DE OF. + 1 OF. ALBAÑIL + 1 AY. OFICIALES) | C29: jor | D29: ='CUADR 2'!H48 -> 1525.2613 | E29: 1 | F29: =D29*E29 -> 1525.2613 | G29: 16 | H29: =F29/G29 -> 95.328828
A30: ='CUADR 3'!C13 -> CUADRILLA no.3 AISLAMIENTOS (0.3 DE CABO DE OF 1 OF. AISLADOR + 2 AYUD OFICIAL.) | C30: jor | D30: ='CUADR 3'!H48 -> 2253.5629 | E30: 1 | F30: =D30*E30 -> 2253.5629 | G30: 16 | H30: =F30/G30 -> 140.84768
